#VRML_SIM R2019a utf8
WorldInfo {
}
Viewpoint {
  orientation 0.9883618329486993 -0.12816469758728713 -0.08194325757892673 5.214072585860952
  position 0.09535181028497577 0.7869572090438255 0.2794727567672016
}
TexturedBackground {
}
TexturedBackgroundLight {
}
Floor {
}
Robot {
  translation 0 0.2 0
  children [
    DEF ROBOT_BODY Shape {
      appearance PBRAppearance {
        baseColor 0.9372549019607843 0.1607843137254902 0.1607843137254902
      }
      geometry DEF G_BODY Box {
        size 0.25 0.07 0.1
      }
    }
    DEF WHEEL1_JOINT HingeJoint {
      jointParameters HingeJointParameters {
        axis 0 0 1
        anchor -0.05 0 0.06
      }
      device [
        RotationalMotor {
          name "motor_right"
        }
      ]
      endPoint DEF WHEEL1 Solid {
        translation -0.05 0 0.06
        rotation 1 0 0 1.5707996938995745
        children [
          Shape {
            appearance PBRAppearance {
              baseColor 0 0 0
              roughness 1
              metalness 0
            }
            geometry DEF G_WHEEL Cylinder {
              height 0.02
              radius 0.075
            }
          }
          DEF WHEEL2_JOINT HingeJoint {
            jointParameters HingeJointParameters {
            }
            device [
              RotationalMotor {
                name "motor_left"
              }
            ]
            endPoint Solid {
              children [
                Shape {
                }
              ]
            }
          }
        ]
        boundingObject USE G_WHEEL
        physics Physics {
        }
      }
    }
  ]
  boundingObject USE G_BODY
  physics Physics {
  }
  controller "robot1"
}
