#VRML_SIM R2019a utf8
WorldInfo {
}
Viewpoint {
  orientation 0.968036772705572 -0.23755285852395552 -0.08045772863360161 5.696535888402278
  position 0.1263049142887278 0.5861385298977357 0.5029126370884431
}
TexturedBackground {
}
TexturedBackgroundLight {
}
Floor {
}
Robot {
  translation 0 0.2 0
  children [
    DEF ROBOT_BODY Shape {
      appearance PBRAppearance {
        baseColor 0.9372549019607843 0.1607843137254902 0.1607843137254902
      }
      geometry DEF G_BODY Box {
        size 0.25 0.07 0.1
      }
    }
    DEF WHEEL1_JOINT HingeJoint {
      jointParameters HingeJointParameters {
        axis 0 0 1
        anchor -0.05 0 0.06
      }
      device [
        RotationalMotor {
          name "motor_right"
        }
      ]
      endPoint DEF WHEEL1 Solid {
        translation -0.05 0 0.06
        rotation 1 0 0 1.5707996938995745
        children [
          Shape {
            appearance PBRAppearance {
              baseColor 0.9882352941176471 0.9137254901960784 0.30980392156862746
              roughness 1
              metalness 0
            }
            geometry DEF G_WHEEL Cylinder {
              height 0.02
              radius 0.075
            }
          }
        ]
        boundingObject USE G_WHEEL
        physics Physics {
        }
      }
    }
  ]
  boundingObject USE G_BODY
  physics Physics {
  }
}
