#VRML_SIM R2019a utf8
WorldInfo {
}
Viewpoint {
  orientation -0.165433981277878 -0.9703918228897376 -0.17598666968632243 1.6966405577672092
  position -0.45415425255574193 0.21187483157447456 0.020058023584592605
}
TexturedBackground {
}
TexturedBackgroundLight {
}
Floor {
}
Robot {
  children [
    Solid {
      translation 0 0.077 0
      children [
        DEF S_BOX Shape {
          appearance PBRAppearance {
            baseColor 0.9372549019607843 0.1607843137254902 0.1607843137254902
            transparency 0.5
          }
          geometry Box {
            size 0.25 0.07 0.1
          }
        }
        HingeJoint {
          jointParameters HingeJointParameters {
            position 0.077
            axis 0 0 1
            anchor 0 0 0.035
          }
          device [
            RotationalMotor {
              name "motor"
            }
          ]
          endPoint Solid {
            translation -0.08687970327448359 -0.0038069752381457945 0.05920085301217247
            rotation 1 -4.906538945149969e-18 -4.906538945149969e-18 1.5707963219999999
            children [
              DEF WHEEL1 Shape {
                appearance PBRAppearance {
                  baseColor 0.9882352941176471 0.9137254901960784 0.30980392156862746
                }
                geometry Cylinder {
                  height 0.02
                  radius 0.075
                }
              }
            ]
            boundingObject USE WHEEL1
            physics Physics {
            }
          }
        }
      ]
    }
  ]
  controller "robot1"
}
